Workbook

Sheet RACI
A1: Function | B1: Activity | C1: AC | D1: DI | E1: AB | F1: NI | G1: OPS | H1: PDS | I1: SS | J1: KL | K1: EH | L1: IT | M1: JH | N1: PC | O1: PR | P1: IF | Q1: CH | R1: WI | S1: TK | T1: CI | U1: Transitions to | V1: Source | W1: Notes
C2: Ayesha Curry | D2: Danielle Iturbe | E2: Alvin Belt | F2: Nicole Iturbe | G2: OPEN | H2: OPEN | I2: Soraya Salgadoe | J2: Kate Le | K2: Erin Hover | L2: Ivy Tan | M2: Jan Haeck | N2: Perrine Calvet | O2: Pedrero Regulatory | P2: Ironclad Finance | Q2: Calm HR | R2: WITHIN | S2: Teknologics | T2: Coastal Interactive
A3: Product Development | B3: Formula stage-gate progression through the PD Formula Tracker | D3: I | E3: R | F3: C | H3: -> | I3: I | N3: A | U3: Product Development Specialist | V3: .claude/skills/asana-pd-manager/references/role-map.md:16; .claude/skills/asana-pd-manager/SKILL.md:60; Alvin, 2026-07-31 (Coastal Interactive; PD visibility) | W3: PD Lead holds technical sign-off on formula stage moves. Operator confirms every move (Rule 1 preview); reversals get a stronger intent check. Perrine and Soraya are never blank on a PD row - PD technical guidance and the marketing read both need visibility on every product decision.
A4: Product Development | B4: Compatibility, stability, RIPT and PET decisions (pre-launch) | E4: C | F4: I | I4: I | N4: A/R | V4: .claude/skills/asana-pd-manager/references/role-map.md:16; Alvin, 2026-07-31 (Coastal Interactive; PD visibility) | W4: PD Lead owns the technical call outright. A and R the same person, and PC is an external contractor. Perrine and Soraya are never blank on a PD row - PD technical guidance and the marketing read both need visibility on every product decision.
A5: Product Development | B5: Packaging development with fillers and component vendors | C5: I | D5: I | E5: C | I5: I | K5: A | L5: C | M5: R | N5: C | V5: .claude/skills/asana-pd-manager/references/role-map.md:16,23; Alvin, 2026-07-31 (role correction); Alvin, 2026-07-31 (Coastal Interactive; PD visibility) | W5: PD Lead owns packaging dev calls; Jan executes packaging and artwork under Erin. Both are contractors. Erin is the lead technical authority on packaging and artwork and answers for the outcome; Jan executes under her. Perrine consults where formula contact or compatibility is in play. Both Erin and Jan are contractors. Perrine and Soraya are never blank on a PD row - PD technical guidance and the marketing read both need visibility on every product decision.
A6: Product Development | B6: Direction-changing PD decisions (launch scope, supplier change, kill calls) | C6: I | D6: A | E6: R | F6: C | I6: I | N6: C | V6: .claude/skills/asana-pd-manager/references/role-map.md:17,18; Alvin, 2026-07-31 (Coastal Interactive; PD visibility) | W6: President approves. PD Consult is final-line approver alongside the President. Perrine and Soraya are never blank on a PD row - PD technical guidance and the marketing read both need visibility on every product decision.
A7: Product Development | B7: Founder approval on brand-line moves | C7: A | D7: C | E7: R | F7: C | I7: I | N7: I | V7: .claude/skills/asana-pd-manager/references/role-map.md:19; Alvin, 2026-07-31 (Coastal Interactive; PD visibility) | W7: Founder gate. Ayesha receives weekly PD signal through the Friday briefing. Perrine and Soraya are never blank on a PD row - PD technical guidance and the marketing read both need visibility on every product decision.
A8: Product Development | B8: PD signal intake from meetings and supplier email, plus PD status reporting | D8: I | E8: A/R | F8: C | H8: -> | I8: I | N8: C | U8: Product Development Specialist | V8: .claude/skills/fireflies-asana-bridge/SKILL.md:287; .claude/skills/outlook-plm-bridge/SKILL.md:191; .claude/skills/sjs-status-reporter/SKILL.md:331,385; Alvin, 2026-07-31 (Coastal Interactive; PD visibility) | W8: Alvin is the named approver on Flow D formula-approval decisions and classifies every meeting item. Covers the three PD hub dashboards. A and R both AB. Perrine and Soraya are never blank on a PD row - PD technical guidance and the marketing read both need visibility on every product decision.
A9: Product Development | B9: Reformulation triggered by a Quality or Regulatory reverse-handoff | D9: I | E9: R | F9: C | I9: I | N9: A | V9: .claude/skills/asana-pd-manager/references/role-map.md:16; .claude/skills/capa-coordinator/SKILL.md:85; Alvin, 2026-07-31 (Coastal Interactive; PD visibility) | W9: PD Lead is cross-flagged for any PD-side reformulation. Reformulation handoff rides the root-cause approval - no separate gate. Perrine and Soraya are never blank on a PD row - PD technical guidance and the marketing read both need visibility on every product decision.
A10: Product Development | B10: Document control: specifications, dielines, artwork versions, BOMs, landed-cost integrity | E10: R | F10: A | H10: -> | I10: I | K10: C | M10: C | N10: C | U10: Product Development Specialist | V10: SharePoint: Sweet July Skin - Product Development Specialist - Job Description.docx; Alvin, 2026-07-31 (Coastal Interactive; PD visibility) | W10: Documentation quality is Nicole's gate. The PD Specialist JD names document control as a core responsibility, so this row transitions on hire. Perrine and Soraya are never blank on a PD row - PD technical guidance and the marketing read both need visibility on every product decision.
A11: Operations & Supply Chain | B11: Vendor master data, onboarding (NDA + W9 gate), sourcing and performance scorecards | E11: A/R | F11: C | G11: -> | I11: C | N11: C | U11: Operations Specialist | V11: .claude/skills/purchasing-manager/SKILL.md:42,46,75,154,158 | W11: PLM vendor record created only after Operations approves at 2D. First-contact routing varies by vendor_type (SKILL.md:50-56) but the approval gate does not. A and R both AB.
A12: Operations & Supply Chain | B12: Purchase order lifecycle: placement, acknowledgement variance, close and discrepancy | E12: A/R | G12: -> | N12: C | U12: Operations Specialist | V12: .claude/skills/purchasing-manager/SKILL.md:108,116,140,248 | W12: Six sub-flows from draft to close, plus Job 10 discrepancy investigation. Every gate is Operations. A and R both AB.
A13: Operations & Supply Chain | B13: Goods receipt on PD-linked purchase orders | E13: R | F13: C | N13: A | V13: .claude/skills/purchasing-manager/SKILL.md:130 | W13: PD owns the close on PD-linked receipts; Purchasing carries the receipt signal only. The one Ops row where accountability sits off the VP seat.
A14: Operations & Supply Chain | B14: Three-way reconciliation across PLM, Shopify and Logiwa | E14: A/R | F14: C | G14: -> | U14: Operations Specialist | V14: .claude/skills/inventory-manager/SKILL.md:68 | W14: Operations decides the correction direction, usually trusting Logiwa as physical reality. A and R both AB.
A15: Operations & Supply Chain | B15: Vendor invoice classification and cost capture (five HITL gates) | D15: I | E15: A/R | F15: C | G15: -> | I15: C | P15: C | U15: Operations Specialist | V15: .claude/skills/purchasing-manager/SKILL.md:234,235,238; Alvin, 2026-07-31 (external partners) | W15: Operator confirms cost_category, regulatory_driver, linked SKU and multi-home routing before any PLM write, and approves the dispute branch. A and R both AB. Ironclad consulted - classified invoices land in their ledger.
A16: Operations & Supply Chain | B16: Inventory position keeping, batch creation on receipt and the location ledger | E16: A/R | F16: I | G16: -> | N16: C | U16: Operations Specialist | V16: .claude/skills/inventory-manager/SKILL.md:18,52,60 | W16: Ex-Ops-Coordinator scope. Alvin took inventory under the 2026-07-17 interim split. A and R both AB.
A17: Operations & Supply Chain | B17: Adjustments, write-offs and return dispositions | E17: A/R | G17: -> | N17: C | U17: Operations Specialist | V17: .claude/skills/inventory-manager/SKILL.md:94 | W17: Operations approves. Near-expiry write-offs wait on the quality call first. A and R both AB.
A18: Operations & Supply Chain | B18: S&OP: forecast, inventory targets and buy recommendations | D18: I | E18: A/R | F18: C | G18: -> | U18: Operations Specialist | V18: .claude/skills/supply-demand-planner/SKILL.md:30-52; .claude/skills/supply-demand-planner/references/plm-schema-additions.md:139 | W18: Operations approves; plm-assistant executes the SQL. Four intertwined jobs on one person. A and R both AB.
A19: Operations & Supply Chain | B19: Inbound freight, customs, duty and carrier claims | E19: A/R | G19: -> | N19: I | U19: Operations Specialist | V19: .claude/skills/logistics-manager/SKILL.md:59,186; .claude/skills/logistics-manager/forms/international-dtc-shipment.md:11 | W19: Nothing created or updated until Operations signs off. Ex-Ops-Coordinator logistics scope, now Alvin. HCT and Impress origin Asia so customs is routine. A and R both AB.
A20: Operations & Supply Chain | B20: Daily DTC order operations and the Logiwa report parse | E20: C | F20: A/R | G20: -> | U20: Operations Specialist | V20: .claude/skills/ayesha-weekly-briefing/SKILL.md:123; .claude/skills/oc3pl-order-manager/SKILL.md:109,191 | W20: Ex-Ops-Coordinator scope. Nicole covers order management and OC3PL under the 2026-07-17 interim split. A and R both NI.
A21: Operations & Supply Chain | B21: Pre-ship out-of-stock holds from the shortage sheet | E21: R | F21: A | G21: -> | U21: Operations Specialist | V21: .claude/skills/oc3pl-order-manager/SKILL.md:201; .claude/skills/ayesha-weekly-briefing/SKILL.md:123 | W21: Order-side holds sit with Nicole; SKU-level shortage routing belongs to inventory-manager, so Alvin does the work.
A22: Operations & Supply Chain | B22: Retailer ASN / EDI 856 and routing-guide compliance (Ulta DC, Amazon Vendor) | D22: I | E22: R | F22: A | G22: -> | U22: Operations Specialist | V22: .claude/skills/logistics-manager/SKILL.md:80; .claude/skills/purchasing-manager/SKILL.md:55 | W22: Operations or Order Ops reviews. UBM launch June 2026 is the deadline driver on this lane.
A23: Operations & Supply Chain | B23: Production scheduling with manufacturing partners | E23: A/R | F23: C | G23: -> | N23: C | U23: Operations Specialist | V23: SharePoint: Sweet July Skin - Operations Specialist - Job Description.docx; Leadership Business Review 2026-07-30 35:18 | W23: Named in the Ops Specialist JD under Planning & Special Projects. Today Alvin coordinates KDC scheduling directly. A and R both AB until the seat is filled.
A24: Quality | B24: Customer complaint intake, classification and first response | E24: R | F24: A | H24: -> | N24: C | U24: Product Development Specialist | V24: .claude/skills/complaint-and-event-handler/SKILL.md:20,53 | W24: HITL on every write. Operator approves classification plus first response. A and R both AB. Gate moved to Nicole as the final quality check per Leadership Business Review 2026-07-30 25:18-26:01.
A25: Quality | B25: Complaint trend analysis by SKU and batch | E25: R | F25: A | H25: -> | N25: C | U25: Product Development Specialist | V25: .claude/skills/quality-manager/references/role-map.md:15 | W25: Voice of Customer holds gates on complaint classification and complaint-driven escalations. Nicole already held this gate; monthly trend review formalizes it per Leadership Business Review 2026-07-30 26:02-26:17.
A26: Quality | B26: NCR and CAPA lifecycle, intake through close (SKN-OPS-001) | D26: I | E26: R | F26: A | H26: -> | N26: C | U26: Product Development Specialist | V26: .claude/skills/capa-coordinator/SKILL.md:54,136; .claude/skills/capa-coordinator/references/ncr-procedure.md:135; .claude/skills/capa-coordinator/references/skn-ops-001.md:64,102 | W26: Operator approves intake and both action plans; QA Lead approves conversion, root cause, verification, effectiveness and close. Six SOP phases, one external contractor on every technical gate. A moved from Perrine to Nicole per Leadership Business Review 2026-07-30 25:18-25:50. Perrine consults on technical root cause.
A27: Quality | B27: Lab finding intake and OOS / OOT classification (SKN-OPS-006) | E27: R | F27: A | H27: -> | N27: C | U27: Product Development Specialist | V27: .claude/skills/quality-lab-coordinator/SKILL.md:48,56 | W27: Operator approves intake and the single-versus-systemic classification. A and R both AB. Gate moved to Nicole per Leadership Business Review 2026-07-30 25:35-25:50. Perrine consults on the technical call.
A28: Quality | B28: Vendor quality flag and scorecard signal back to Purchasing | E28: R | F28: A | H28: -> | N28: C | U28: Product Development Specialist | V28: .claude/skills/quality-lab-coordinator/SKILL.md:76; .claude/skills/quality-lab-coordinator/references/vendor-scorecard-signal.md:103 | W28: QA Lead approves any vendor flag and the scorecard band. Operator can stage but not commit. A moved from Perrine to Nicole per Leadership Business Review 2026-07-30 25:18-25:50. Perrine consults.
A29: Quality | B29: Batch hold and release (SKN-OPS-007) | D29: I | E29: R | F29: A | H29: -> | N29: C | U29: Product Development Specialist | V29: .claude/skills/batch-lifecycle-tracker/references/batch-lifecycle-procedure.md:208; .claude/skills/batch-lifecycle-tracker/SKILL.md:86 | W29: QA Lead approves every hold and every release. No exceptions at v5.4. Releases need a CAPA close or clean retest plus QA Lead judgment. A moved from Perrine to Nicole per Leadership Business Review 2026-07-30 25:35-26:01. Perrine consults on the technical basis.
A30: Quality | B30: In-market stability testing decisions (PET, accelerated, real-time) | E30: R | F30: C | H30: -> | N30: A | U30: Product Development Specialist | V30: .claude/skills/batch-lifecycle-tracker/SKILL.md:71,94 | W30: Technical testing call stays with Perrine as the R&D and quality technical advisor. Operator approves schedule edits. Per Leadership Business Review 2026-07-30 25:18-25:35 the process gate moved to Nicole but the technical judgment did not.
A31: Quality | B31: Near-expiry batch disposition at the 30-day threshold | E31: R | F31: A | H31: -> | N31: C | U31: Product Development Specialist | V31: .claude/skills/batch-lifecycle-tracker/SKILL.md:71,94 | W31: Disposition is a quality gate, so it moves to Nicole. Posts back to inventory before any write-off.
A32: Quality | B32: Serious adverse event triage and recall kickoff (SKN-OPS-002, SKN-OPS-003) | C32: I | D32: I | E32: A/R | F32: C | N32: C | O32: C | V32: .claude/skills/complaint-and-event-handler/SKILL.md:85,89,95; .claude/skills/regulatory-manager/references/pedrero-contacts.md:9,13,21 | W32: The strictest gate in the suite: explicit approval at every step, §4.A through §4.F each a separate gate. Operator decides severity, team and whether external reporting is needed. A and R both AB. Stays with Alvin as Reg Lead, given the legal and agency exposure. Nicole consults. Pedrero Regulatory holds the binding external review; consult-only internally, with no Asana access and no internal authority, so the Reg Lead gate stays in-house.
A33: Quality | B33: SOP ratification, annual review and cross-cutting quality tasks | E33: R | F33: A | N33: C | V33: .claude/skills/quality-manager/SKILL.md:66,135; .claude/skills/quality-manager/references/sop-catalog.md:120; .claude/skills/quality-manager/references/qos-thresholds.md:52 | W33: QA Lead approves every ratification, review outcome, cross-cutting task and QoS threshold task. SOP §7 names a QA Manager for this; that seat is vacant and Perrine is filling it. Gate moved to Nicole per Leadership Business Review 2026-07-30 25:18-25:50.
A34: Quality | B34: Quality dashboard publish to the landing hub | E34: R | F34: A | H34: -> | N34: C | U34: Product Development Specialist | V34: .claude/skills/quality-status-reporter/SKILL.md:78 | W34: Operator approves the commit before push. Never commit without confirmation. A and R both AB. Nicole gates the content; Alvin retains the publish mechanics. Per Leadership Business Review 2026-07-30 26:02-26:17.
A35: Quality | B35: Final quality check on product and documentation across every function | C35: I | D35: I | E35: C | F35: A/R | I35: C | K35: C | N35: C | V35: Leadership Business Review 2026-07-30 25:35-26:01 | W35: The new cross-function gate. Verbatim: "anything related to quality of service or quality of product will go through Nicole's eyes as sort of that final quality check... Even with each function having or being the primary owner, we'll still have that quality gate." A and R both NI.
A36: Quality | B36: Quality management system framework and monthly quality-trend review | D36: I | E36: A | F36: R | N36: C | V36: Leadership Business Review 2026-07-30 25:18-26:17 | W36: Alvin owns the overall framework; Nicole runs it. Monthly trend review so recurring issues (the pump issue was the worked example) can drive packaging or formula decisions. Target: implemented by end of Q3.
A37: Regulatory & Compliance | B37: Pre-launch ingredient list review gate (SKN-OPS-008) | E37: A/R | F37: I | H37: -> | N37: C | O37: C | U37: Product Development Specialist | V37: .claude/skills/claims-il-and-label-keeper/SKILL.md:50; .claude/skills/claims-il-and-label-keeper/references/il-claims-label-procedure.md:62; .claude/skills/regulatory-manager/references/pedrero-contacts.md:9,13,21 | W37: Operator approves intake. Reg Lead is the same person at v6.6, so the gate fires twice against one person. Pedrero holds the binding external call. A and R both AB. Pedrero Regulatory holds the binding external review; consult-only internally, with no Asana access and no internal authority, so the Reg Lead gate stays in-house.
A38: Regulatory & Compliance | B38: Pedrero engagement and send approval | E38: A/R | N38: C | O38: C | V38: .claude/skills/claims-il-and-label-keeper/SKILL.md:60; .claude/skills/regulatory-manager/SKILL.md:140; .claude/skills/regulatory-manager/references/pedrero-contacts.md:9,13,21 | W38: Reg Lead approves every Pedrero send; Operator hits send manually. Both roles are Alvin. A and R both AB. Pedrero Regulatory holds the binding external review; consult-only internally, with no Asana access and no internal authority, so the Reg Lead gate stays in-house.
A39: Regulatory & Compliance | B39: Claim substantiation and new-claim defensibility | C39: C | D39: I | E39: A/R | H39: -> | I39: C | K39: C | N39: C | O39: C | U39: Product Development Specialist | V39: .claude/skills/claims-il-and-label-keeper/SKILL.md:97; .claude/skills/claims-il-and-label-keeper/references/il-claims-label-procedure.md:29; Alvin, 2026-07-31 (role correction); .claude/skills/regulatory-manager/references/pedrero-contacts.md:9,13,21 | W39: Operator approves the path; Reg Lead approves the Pedrero stage. The procedure exists because new claims from marketing or the founder used to skip Pedrero sign-off. A and R both AB. The procedure exists because new claims from marketing or the founder used to skip Pedrero sign-off, so both are consulted rather than bypassed. Pedrero Regulatory holds the binding external review; consult-only internally, with no Asana access and no internal authority, so the Reg Lead gate stays in-house.
A40: Regulatory & Compliance | B40: Label artwork archive, IL cross-check and label-law checks (Pantone, Canada, Quebec, 19-state toxics) | C40: C | D40: I | E40: R | F40: C | K40: A | M40: C | N40: C | O40: C | V40: .claude/skills/claims-il-and-label-keeper/SKILL.md:85; .claude/skills/claims-il-and-label-keeper/references/il-claims-label-procedure.md:93; Alvin, 2026-07-31 (role correction); .claude/skills/regulatory-manager/references/pedrero-contacts.md:9,13,21 | W40: Operator approves each pass outcome; Reg Lead approves any archive entry. Creative produces the artwork under review. Erin answers for the artwork being right as lead technical authority. Alvin runs the IL cross-check and the label-law passes and holds the Reg Lead gate on archive entries, so the regulatory approval and the artwork authority are separate people. Pedrero Regulatory holds the binding external review; consult-only internally, with no Asana access and no internal authority, so the Reg Lead gate stays in-house.
...

Sheet Analysis
A1: Ownership concentration, coverage gaps, and what the two seats move
A3: Counts are live formulas over the RACI sheet, so they move if a row changes. Read against the matrix. Reflects the 30 July 2026 leadership review and the 31 July role corrections.
A5: Position and holder | B5: A | C5: R | D5: A/R | E5: Hands off | F5: Absorbs | G5: A after | H5: R after
A6: AC: Owner / Founder (Ayesha Curry) | B6: =COUNTIF(RACI!C3:C104,"A")+COUNTIF(RACI!C3:C104,"A/R") | C6: =COUNTIF(RACI!C3:C104,"R")+COUNTIF(RACI!C3:C104,"A/R") | D6: =COUNTIF(RACI!C3:C104,"A/R") | E6: 0 | F6: 0 | G6: =B6 | H6: =C6-E6+F6
A7: DI: President (Danielle Iturbe) | B7: =COUNTIF(RACI!D3:D104,"A")+COUNTIF(RACI!D3:D104,"A/R") | C7: =COUNTIF(RACI!D3:D104,"R")+COUNTIF(RACI!D3:D104,"A/R") | D7: =COUNTIF(RACI!D3:D104,"A/R") | E7: 0 | F7: 0 | G7: =B7 | H7: =C7-E7+F7
A8: AB: VP of Operations (Alvin Belt) | B8: =COUNTIF(RACI!E3:E104,"A")+COUNTIF(RACI!E3:E104,"A/R") | C8: =COUNTIF(RACI!E3:E104,"R")+COUNTIF(RACI!E3:E104,"A/R") | D8: =COUNTIF(RACI!E3:E104,"A/R") | E8: 30 | F8: 0 | G8: =B8 | H8: =C8-E8+F8
A9: NI: Sr. Director, Consumer Strategy & Operations (Nicole Iturbe) | B9: =COUNTIF(RACI!F3:F104,"A")+COUNTIF(RACI!F3:F104,"A/R") | C9: =COUNTIF(RACI!F3:F104,"R")+COUNTIF(RACI!F3:F104,"A/R") | D9: =COUNTIF(RACI!F3:F104,"A/R") | E9: 3 | F9: 0 | G9: =B9 | H9: =C9-E9+F9
A10: OPS: Operations Specialist (Open seat) | B10: =COUNTIF(RACI!G3:G104,"A")+COUNTIF(RACI!G3:G104,"A/R") | C10: =COUNTIF(RACI!G3:G104,"R")+COUNTIF(RACI!G3:G104,"A/R") | D10: =COUNTIF(RACI!G3:G104,"A/R") | E10: 0 | F10: 18 | G10: =B10 | H10: =C10-E10+F10
A11: PDS: Product Development Specialist (Open seat) | B11: =COUNTIF(RACI!H3:H104,"A")+COUNTIF(RACI!H3:H104,"A/R") | C11: =COUNTIF(RACI!H3:H104,"R")+COUNTIF(RACI!H3:H104,"A/R") | D11: =COUNTIF(RACI!H3:H104,"A/R") | E11: 0 | F11: 16 | G11: =B11 | H11: =C11-E11+F11
A12: SS: Marketing Manager (Soraya Salgadoe) | B12: =COUNTIF(RACI!I3:I104,"A")+COUNTIF(RACI!I3:I104,"A/R") | C12: =COUNTIF(RACI!I3:I104,"R")+COUNTIF(RACI!I3:I104,"A/R") | D12: =COUNTIF(RACI!I3:I104,"A/R") | E12: 0 | F12: 0 | G12: =B12 | H12: =C12-E12+F12
A13: KL: Social Media Coordinator (Kate Le) | B13: =COUNTIF(RACI!J3:J104,"A")+COUNTIF(RACI!J3:J104,"A/R") | C13: =COUNTIF(RACI!J3:J104,"R")+COUNTIF(RACI!J3:J104,"A/R") | D13: =COUNTIF(RACI!J3:J104,"A/R") | E13: 0 | F13: 0 | G13: =B13 | H13: =C13-E13+F13
A14: EH: Creative Director (Erin Hover) | B14: =COUNTIF(RACI!K3:K104,"A")+COUNTIF(RACI!K3:K104,"A/R") | C14: =COUNTIF(RACI!K3:K104,"R")+COUNTIF(RACI!K3:K104,"A/R") | D14: =COUNTIF(RACI!K3:K104,"A/R") | E14: 0 | F14: 0 | G14: =B14 | H14: =C14-E14+F14
A15: IT: Creative / Design Coordinator (Ivy Tan) | B15: =COUNTIF(RACI!L3:L104,"A")+COUNTIF(RACI!L3:L104,"A/R") | C15: =COUNTIF(RACI!L3:L104,"R")+COUNTIF(RACI!L3:L104,"A/R") | D15: =COUNTIF(RACI!L3:L104,"A/R") | E15: 0 | F15: 0 | G15: =B15 | H15: =C15-E15+F15
A16: JH: Packaging Engineer (Jan Haeck) | B16: =COUNTIF(RACI!M3:M104,"A")+COUNTIF(RACI!M3:M104,"A/R") | C16: =COUNTIF(RACI!M3:M104,"R")+COUNTIF(RACI!M3:M104,"A/R") | D16: =COUNTIF(RACI!M3:M104,"A/R") | E16: 0 | F16: 0 | G16: =B16 | H16: =C16-E16+F16
A17: PC: PD / R&D contractor, Milinyc (Perrine Calvet) | B17: =COUNTIF(RACI!N3:N104,"A")+COUNTIF(RACI!N3:N104,"A/R") | C17: =COUNTIF(RACI!N3:N104,"R")+COUNTIF(RACI!N3:N104,"A/R") | D17: =COUNTIF(RACI!N3:N104,"A/R") | E17: 0 | F17: 0 | G17: =B17 | H17: =C17-E17+F17
A18: PR: External regulatory partner (Pedrero Regulatory) | B18: =COUNTIF(RACI!O3:O104,"A")+COUNTIF(RACI!O3:O104,"A/R") | C18: =COUNTIF(RACI!O3:O104,"R")+COUNTIF(RACI!O3:O104,"A/R") | D18: =COUNTIF(RACI!O3:O104,"A/R") | E18: 0 | F18: 0 | G18: =B18 | H18: =C18-E18+F18
A19: IF: Outsourced finance (Dan Bender) (Ironclad Finance) | B19: =COUNTIF(RACI!P3:P104,"A")+COUNTIF(RACI!P3:P104,"A/R") | C19: =COUNTIF(RACI!P3:P104,"R")+COUNTIF(RACI!P3:P104,"A/R") | D19: =COUNTIF(RACI!P3:P104,"A/R") | E19: 0 | F19: 0 | G19: =B19 | H19: =C19-E19+F19
A20: CH: PEO and co-employer (Calm HR) | B20: =COUNTIF(RACI!Q3:Q104,"A")+COUNTIF(RACI!Q3:Q104,"A/R") | C20: =COUNTIF(RACI!Q3:Q104,"R")+COUNTIF(RACI!Q3:Q104,"A/R") | D20: =COUNTIF(RACI!Q3:Q104,"A/R") | E20: 0 | F20: 0 | G20: =B20 | H20: =C20-E20+F20
A21: WI: Digital marketing agency (WITHIN) | B21: =COUNTIF(RACI!R3:R104,"A")+COUNTIF(RACI!R3:R104,"A/R") | C21: =COUNTIF(RACI!R3:R104,"R")+COUNTIF(RACI!R3:R104,"A/R") | D21: =COUNTIF(RACI!R3:R104,"A/R") | E21: 0 | F21: 0 | G21: =B21 | H21: =C21-E21+F21
A22: TK: Web development (Teknologics) | B22: =COUNTIF(RACI!S3:S104,"A")+COUNTIF(RACI!S3:S104,"A/R") | C22: =COUNTIF(RACI!S3:S104,"R")+COUNTIF(RACI!S3:S104,"A/R") | D22: =COUNTIF(RACI!S3:S104,"A/R") | E22: 0 | F22: 0 | G22: =B22 | H22: =C22-E22+F22
A23: CI: Managed IT service provider (Coastal Interactive) | B23: =COUNTIF(RACI!T3:T104,"A")+COUNTIF(RACI!T3:T104,"A/R") | C23: =COUNTIF(RACI!T3:T104,"R")+COUNTIF(RACI!T3:T104,"A/R") | D23: =COUNTIF(RACI!T3:T104,"A/R") | E23: 1 | F23: 0 | G23: =B23 | H23: =C23-E23+F23
A24: Total activities | B24: =COUNTA(RACI!B3:B104)
A26: "A after" and "R after" project the book once both specialist seats are filled. Hands off counts rows where this position does the work today and an incoming seat takes it. Absorbs counts rows arriving on hire.
A28: Quality now has a gate, and it is not the VP
A30: The 30 July leadership review moved the quality function onto Nicole. Verbatim from the recording: "Nicole taking the primary focus on the quality management side of things with quality control... anything related to quality of service or quality of product will go through Nicole's eyes as sort of that final quality check... Even with each function having or being the primary owner, we'll still have that quality gate." That shows up as 10 of the 13 Quality rows accountable to Nicole, against 2 for Alvin and 1 for Perrine. Her total book of accountability goes from 8 rows to 21.
A32: Perrine moves to technical guidance
A34: She keeps A on the 7 rows where the judgment is genuinely formulation - formula stage-gate, compatibility and stability and RIPT and PET, in-market stability testing, reformulation, PD-linked receipt, and the two margin rows that turn on formulation cost. Packaging development moved to Erin Hover as the lead technical authority on packaging and artwork. She moves to consulted on everything process-shaped: NCR and CAPA lifecycle, batch hold and release, vendor quality flags, lab finding classification, SOP ratification. Danielle's framing in the review was that there were things the team had assumed Perrine would manage or organize that she is not, and that leadership can pull the plug even when she has submitted an approval. Splitting technical judgment from process ownership is what that means in practice.
A36: Three contractors hold accountability, and two of them hold it alone
A38: Erin Hover is the lead technical authority on packaging and artwork and is accountable for 4 rows - creative direction, packaging development, artwork execution, and the label artwork archive. She is also a contractor, and on creative direction she is both A and R with no internal counterpart. Jan Haeck, who executes under her, is a contractor too, so the whole packaging and artwork chain runs through people outside the company. Perrine Calvet is the third, accountable for 7 formulation rows. Between them that is 11 of 79 activities where nobody on staff can check the work or continue it. Neither specialist job description covers creative or formulation authority, so the two hires do not close this.
A40: Nobody is blank on a product decision
A42: Perrine and Soraya now hold a letter on all eight Product Development rows. Perrine was blank on one - founder brand-line approval - and Soraya was blank on all eight, which meant the marketing read had no formal visibility into any product decision. Both are Informed at minimum now. That is a small change with a real effect: a blank cell on a RACI is ambiguous in a way that Informed is not, because blank does not tell you whether the omission was deliberate.
A44: Marketing and the channels finally have owners with real activities under them
A46: Soraya goes from 1 accountable row to 8. Marketing now carries editorial calendar, Klaviyo email, paid media, social content, influencer and earned media, the WITHIN relationship, product copy and PDP content - none of which existed on the matrix before, because none of it has a skill behind it. Nicole goes from 21 to 26 with all-channel accountability plus wholesale pipeline, retail price architecture and the retailer promo calendar. Retail & Wholesale went from 2 rows to 5, Marketing from 9 to 15. A skill suite is a good source for what is automated; it is a poor source for what a business does.
A48: Where the President and the Founder sit
... A86: Perrine is an external contractor holding A on 8 rows with no internal counterpart, and one of those - compatibility and stability and RIPT and PET - has her as both A and R. Nobody inside AC Brands can check that work or continue it. Alvin is the other: the Operator gate has no alternate anywhere in the suite, and all 23 scheduled Routines stop at a human approval only he can clear. Succession is documented exactly once in the entire system, for competitive intelligence. Nothing comparable exists for the quality gate, the technical advisor, or the framework owner. That gap costs hours to close, not headcount, and it is the one I would fix first.

Sheet Gaps
A1: Type | B1: Function | C1: Gap | D1: Why it matters | E1: Owner / next step | F1: Est. hrs / month | G1: Source
A2: Open seat | B2: Operations & Supply Chain | C2: Operations Specialist. Approved, prioritized, recruiting now. Reports to Nicole. $72-90K. | D2: Alvin does the work on 11 of 12 Operations rows. This seat absorbs 16 activities across order ops, inventory, purchase-to-pay, freight and planning. | E2: Recruiting via Calm HR once the RACI clears Danielle | F2: 160 | G2: decisions/log.md:52; Leadership Business Review 2026-07-30 52:48-53:17; Ops Specialist JD
A3: Open seat | B3: Product Development | C3: PD Specialist. Approved, phased in after Ops. Reports to Nicole. $75-95K. | D3: Absorbs 16 activities including the whole quality-execution layer the JD calls 'run the quality system', plus document control and product regulatory work. Until then Nicole gates and Alvin executes. | E3: Define scope, then recruit after Ops seat lands | F3: 160 | G3: decisions/log.md:52; Leadership Business Review 2026-07-30 53:17-57:10; PD Specialist JD
A4: Resolved | B4: Finance | C4: Finance is owned. Ironclad Finance (Dan Bender) runs AP, bookkeeping, payroll, month-end close and reporting. Danielle accountable for reporting, Alvin for cost. | D4: Was flagged as unowned before the external partners were added to the matrix. The remaining question is not ownership but coverage: no internal finance headcount exists, so continuity depends on the Ironclad engagement. | E4: No action - confirm engagement terms and renewal date | F4: 0 | G4: Alvin, 2026-07-31 (external partners)
A5: Resolved | B5: People & Admin | C5: HR is owned. Calm HR is the PEO and co-employer and runs handbook, policy, benefits, payroll admin, onboarding, offboarding and separations. Alvin accountable as liaison, Danielle co-approves. | D5: Was flagged as unowned before the external partners were added. What remains internal is the system-side half of offboarding - Asana reassignment, wiki contact state, access deprovisioning - which the departed-role-holder checklist covers and which is still on Alvin. | E5: No action on HR; system-side offboarding to the Ops Specialist | F5: 4 | G5: Alvin, 2026-07-31 (external partners); asana-pd-manager/references/role-map.md:48-56
A6: Resolved | B6: Ecommerce & DTC | C6: Shopify revenue and channel position is owned. Nicole is accountable for all channels - DTC, Amazon and wholesale - with Alvin doing the work and Danielle informed. | D6: Was the last row on the matrix with no owner. The landing hub had split DTC and Amazon to Alvin and left wholesale as TBD; consolidating all channels under one accountability closes it. | E6: No action - every row on the matrix now has an owner | F6: 0 | G6: acb-thelanding: data/links.json; Alvin, 2026-07-31 (marketing, wholesale and web)
A7: Resolved | B7: Marketing & Brand | C7: Marketing is owned. Soraya is accountable across editorial, email, paid media and social. WITHIN responsible for paid and email execution, Kate for social content. | D7: The landing hub listed Marketing as "Owned by TBD" with four named tools and nobody against them. Fifteen Marketing rows now have an owner. | E7: No action - confirm WITHIN engagement terms and renewal | F7: 0 | G7: acb-thelanding: data/links.json; Alvin, 2026-07-31 (marketing, wholesale and web)
A8: Single point of failure | B8: Product Development | C8: Compatibility, stability, RIPT and PET decisions sit with an external contractor as both A and R. | D8: No internal counterpart can check the work or continue it. Pre-launch technical decisions have no second reader. | E8: PD Specialist as internal counterpart on hire | F8: 0 | G8: asana-pd-manager/references/role-map.md:16
A9: Concentration | B9: All functions | C9: Six whole functions run through external partner organisations: Regulatory (Pedrero), Finance (Ironclad), HR (Calm HR), digital marketing (WITHIN), web development (Teknologics), managed IT (Coastal Interactive). Plus three contractors on packaging, creative and formulation. | D9: Nine external parties hold the execution of Regulatory, Finance, HR, digital marketing, web development, managed IT, packaging, creative and formulation. Not a fault - it is how a team of nine covers this surface - but continuity rests on nine engagements rather than on employment, and each one is a renewal decision. Engagement terms are recorded for Pedrero only. | E9: Record engagement terms and renewal dates for all nine | F9: 0 | G9: Alvin, 2026-07-31 (external partners)
A10: Single point of failure | B10: Regulatory & Compliance | C10: Pedrero forms every regulatory opinion but holds no accountability, and Alvin performs every regulatory action. Consulted on 11 rows, responsible for none. | D10: Our own procedures make Pedrero consult-only with no Asana access and no internal authority, so the binding external call and the internal execution are both bottlenecks in different ways: their opinion gates the work, and only Alvin can act on it. | E10: Give the Reg Lead gate an alternate, or widen Pedrero's remit | F10: 0 | G10: regulatory-manager/references/pedrero-contacts.md:9,13,21
A11: Single point of failure | B11: Creative | C11: Erin Hover is a contractor and the lead technical authority on packaging and artwork, accountable for 4 rows with no internal backup. On creative direction she is both A and R. | D11: Jan Haeck executes under her and is also a contractor, so the entire packaging and artwork chain sits outside the company. Neither approved job description covers creative authority. | E11: Name an internal creative counterpart, or scope it into a future role | F11: 0 | G11: Alvin, 2026-07-31 (role correction); asana-pd-manager/references/role-map.md:22-23
A12: Single point of failure | B12: Quality | C12: Perrine holds A on 7 formulation rows as a contractor, with no named backup. | D12: Reduced from 11 by moving process gates to Nicole and packaging to Erin, which is real progress. What remains is genuinely formulation and genuinely single-threaded. | E12: Name a backup technical reviewer | F12: 0 | G12: Leadership Business Review 2026-07-30 25:18-25:50; quality-manager/references/role-map.md:14
A13: Single point of failure | B13: Regulatory & Compliance | C13: Operator and Reg Lead are the same person, so two gates designed to be independent fire against one approver. | D13: On ingredient-list packets, retailer attestations and FDA filings the second approval adds an audit entry but no second judgment. The 15-day reporting clock has no alternate. | E13: Split Reg Lead, or route the second gate to Pedrero | F13: 0 | G13: regulatory-manager/references/role-map.md:14; adverse-event-and-recall-reporter/SKILL.md:108
... A21: Uncovered brand | B21: All functions | C21: Sweet July, the lifestyle brand, has no coverage. The suite is Sweet July Skin plus company-wide work. | D21: Merch, licensing and non-skincare retail are run somewhere, but nothing documents who owns them. They cannot be put on a RACI from these sources. | E21: Danielle to confirm scope for the next version | F21: 0 | G21: references/architecture/system_map.md:3; context/about-business.md:3
A23: Hours per month | C23: Rough estimates. Open-seat rows are full-time-equivalent load, not incremental. Zero means the gap is a structural exposure rather than unbilled hours.
